2020-04-14 09:13:19,709 ERROR: Exception on /login [GET] [in c:\users\vogel\appdata\local\programs\python\python38-32\lib\site-packages\flask\app.py:1890]
Traceback (most recent call last):
  File "c:\users\vogel\appdata\local\programs\python\python38-32\lib\site-packages\flask\app.py", line 2446, in wsgi_app
    response = self.full_dispatch_request()
  File "c:\users\vogel\appdata\local\programs\python\python38-32\lib\site-packages\flask\app.py", line 1951, in full_dispatch_request
    rv = self.handle_user_exception(e)
  File "c:\users\vogel\appdata\local\programs\python\python38-32\lib\site-packages\flask\app.py", line 1820, in handle_user_exception
    reraise(exc_type, exc_value, tb)
  File "c:\users\vogel\appdata\local\programs\python\python38-32\lib\site-packages\flask\_compat.py", line 39, in reraise
    raise value
  File "c:\users\vogel\appdata\local\programs\python\python38-32\lib\site-packages\flask\app.py", line 1949, in full_dispatch_request
    rv = self.dispatch_request()
  File "c:\users\vogel\appdata\local\programs\python\python38-32\lib\site-packages\flask\app.py", line 1935, in dispatch_request
    return self.view_functions[rule.endpoint](**req.view_args)
  File "C:\Users\vogel\OneDrive\Desktop\CoronaLMS\app\routes.py", line 49, in login
    form = LoginForm()
  File "c:\users\vogel\appdata\local\programs\python\python38-32\lib\site-packages\wtforms\form.py", line 212, in __call__
    return type.__call__(cls, *args, **kwargs)
  File "c:\users\vogel\appdata\local\programs\python\python38-32\lib\site-packages\flask_wtf\form.py", line 87, in __init__
    super(FlaskForm, self).__init__(formdata=formdata, **kwargs)
  File "c:\users\vogel\appdata\local\programs\python\python38-32\lib\site-packages\wtforms\form.py", line 272, in __init__
    super(Form, self).__init__(self._unbound_fields, meta=meta_obj, prefix=prefix)
  File "c:\users\vogel\appdata\local\programs\python\python38-32\lib\site-packages\wtforms\form.py", line 52, in __init__
    field = meta.bind_field(self, unbound_field, options)
  File "c:\users\vogel\appdata\local\programs\python\python38-32\lib\site-packages\wtforms\meta.py", line 27, in bind_field
    return unbound_field.bind(form=form, **options)
  File "c:\users\vogel\appdata\local\programs\python\python38-32\lib\site-packages\wtforms\fields\core.py", line 353, in bind
    return self.field_class(*self.args, **kw)
  File "c:\users\vogel\appdata\local\programs\python\python38-32\lib\site-packages\wtforms\fields\core.py", line 702, in __init__
    super(BooleanField, self).__init__(label, validators, **kwargs)
TypeError: __init__() got an unexpected keyword argument 'class'
2020-04-14 09:13:42,211 INFO: Corona LMS startup [in C:\Users\vogel\OneDrive\Desktop\CoronaLMS\app\__init__.py:38]
2020-04-14 21:05:53,031 INFO: Corona LMS startup [in C:\Users\vogel\OneDrive\Desktop\CoronaLMS\app\__init__.py:38]
2020-04-14 21:06:05,727 ERROR: Exception on /login [GET] [in c:\users\vogel\appdata\local\programs\python\python38-32\lib\site-packages\flask\app.py:1890]
Traceback (most recent call last):
  File "c:\users\vogel\appdata\local\programs\python\python38-32\lib\site-packages\flask\app.py", line 2446, in wsgi_app
    response = self.full_dispatch_request()
  File "c:\users\vogel\appdata\local\programs\python\python38-32\lib\site-packages\flask\app.py", line 1951, in full_dispatch_request
    rv = self.handle_user_exception(e)
  File "c:\users\vogel\appdata\local\programs\python\python38-32\lib\site-packages\flask\app.py", line 1820, in handle_user_exception
    reraise(exc_type, exc_value, tb)
  File "c:\users\vogel\appdata\local\programs\python\python38-32\lib\site-packages\flask\_compat.py", line 39, in reraise
    raise value
  File "c:\users\vogel\appdata\local\programs\python\python38-32\lib\site-packages\flask\app.py", line 1949, in full_dispatch_request
    rv = self.dispatch_request()
  File "c:\users\vogel\appdata\local\programs\python\python38-32\lib\site-packages\flask\app.py", line 1935, in dispatch_request
    return self.view_functions[rule.endpoint](**req.view_args)
  File "C:\Users\vogel\OneDrive\Desktop\CoronaLMS\app\routes.py", line 63, in login
    return render_template('login.html', title='Login', form=form)
  File "c:\users\vogel\appdata\local\programs\python\python38-32\lib\site-packages\flask\templating.py", line 137, in render_template
    return _render(
  File "c:\users\vogel\appdata\local\programs\python\python38-32\lib\site-packages\flask\templating.py", line 120, in _render
    rv = template.render(context)
  File "c:\users\vogel\appdata\local\programs\python\python38-32\lib\site-packages\jinja2\environment.py", line 1090, in render
    self.environment.handle_exception()
  File "c:\users\vogel\appdata\local\programs\python\python38-32\lib\site-packages\jinja2\environment.py", line 832, in handle_exception
    reraise(*rewrite_traceback_stack(source=source))
  File "c:\users\vogel\appdata\local\programs\python\python38-32\lib\site-packages\jinja2\_compat.py", line 28, in reraise
    raise value.with_traceback(tb)
  File "C:\Users\vogel\OneDrive\Desktop\CoronaLMS\app\templates\login.html", line 1, in top-level template code
    {% extends "base.html" %}
  File "c:\users\vogel\appdata\local\programs\python\python38-32\lib\site-packages\jinja2\environment.py", line 832, in handle_exception
    reraise(*rewrite_traceback_stack(source=source))
  File "c:\users\vogel\appdata\local\programs\python\python38-32\lib\site-packages\jinja2\_compat.py", line 28, in reraise
    raise value.with_traceback(tb)
  File "C:\Users\vogel\OneDrive\Desktop\CoronaLMS\app\templates\base.html", line 27, in template
    <a class="nav-link" href="{{ url_for('index') }}">Kursübersicht</a>
jinja2.exceptions.TemplateSyntaxError: expected token ',', got 'index'
2020-04-14 21:06:06,341 ERROR: Exception on /login [GET] [in c:\users\vogel\appdata\local\programs\python\python38-32\lib\site-packages\flask\app.py:1890]
Traceback (most recent call last):
  File "c:\users\vogel\appdata\local\programs\python\python38-32\lib\site-packages\flask\app.py", line 2446, in wsgi_app
    response = self.full_dispatch_request()
  File "c:\users\vogel\appdata\local\programs\python\python38-32\lib\site-packages\flask\app.py", line 1951, in full_dispatch_request
    rv = self.handle_user_exception(e)
  File "c:\users\vogel\appdata\local\programs\python\python38-32\lib\site-packages\flask\app.py", line 1820, in handle_user_exception
    reraise(exc_type, exc_value, tb)
  File "c:\users\vogel\appdata\local\programs\python\python38-32\lib\site-packages\flask\_compat.py", line 39, in reraise
    raise value
  File "c:\users\vogel\appdata\local\programs\python\python38-32\lib\site-packages\flask\app.py", line 1949, in full_dispatch_request
    rv = self.dispatch_request()
  File "c:\users\vogel\appdata\local\programs\python\python38-32\lib\site-packages\flask\app.py", line 1935, in dispatch_request
    return self.view_functions[rule.endpoint](**req.view_args)
  File "C:\Users\vogel\OneDrive\Desktop\CoronaLMS\app\routes.py", line 63, in login
    return render_template('login.html', title='Login', form=form)
  File "c:\users\vogel\appdata\local\programs\python\python38-32\lib\site-packages\flask\templating.py", line 137, in render_template
    return _render(
  File "c:\users\vogel\appdata\local\programs\python\python38-32\lib\site-packages\flask\templating.py", line 120, in _render
    rv = template.render(context)
  File "c:\users\vogel\appdata\local\programs\python\python38-32\lib\site-packages\jinja2\environment.py", line 1090, in render
    self.environment.handle_exception()
  File "c:\users\vogel\appdata\local\programs\python\python38-32\lib\site-packages\jinja2\environment.py", line 832, in handle_exception
    reraise(*rewrite_traceback_stack(source=source))
  File "c:\users\vogel\appdata\local\programs\python\python38-32\lib\site-packages\jinja2\_compat.py", line 28, in reraise
    raise value.with_traceback(tb)
  File "C:\Users\vogel\OneDrive\Desktop\CoronaLMS\app\templates\login.html", line 1, in top-level template code
    {% extends "base.html" %}
  File "c:\users\vogel\appdata\local\programs\python\python38-32\lib\site-packages\jinja2\environment.py", line 832, in handle_exception
    reraise(*rewrite_traceback_stack(source=source))
  File "c:\users\vogel\appdata\local\programs\python\python38-32\lib\site-packages\jinja2\_compat.py", line 28, in reraise
    raise value.with_traceback(tb)
  File "C:\Users\vogel\OneDrive\Desktop\CoronaLMS\app\templates\base.html", line 27, in template
    <a class="nav-link" href="{{ url_for('index') }}">Kursübersicht</a>
jinja2.exceptions.TemplateSyntaxError: expected token ',', got 'index'
