2020-04-14 21:07:13,849 ERROR: Exception on /login [GET] [in c:\users\vogel\appdata\local\programs\python\python38-32\lib\site-packages\flask\app.py:1890]
Traceback (most recent call last):
  File "c:\users\vogel\appdata\local\programs\python\python38-32\lib\site-packages\flask\app.py", line 2446, in wsgi_app
    response = self.full_dispatch_request()
  File "c:\users\vogel\appdata\local\programs\python\python38-32\lib\site-packages\flask\app.py", line 1951, in full_dispatch_request
    rv = self.handle_user_exception(e)
  File "c:\users\vogel\appdata\local\programs\python\python38-32\lib\site-packages\flask\app.py", line 1820, in handle_user_exception
    reraise(exc_type, exc_value, tb)
  File "c:\users\vogel\appdata\local\programs\python\python38-32\lib\site-packages\flask\_compat.py", line 39, in reraise
    raise value
  File "c:\users\vogel\appdata\local\programs\python\python38-32\lib\site-packages\flask\app.py", line 1949, in full_dispatch_request
    rv = self.dispatch_request()
  File "c:\users\vogel\appdata\local\programs\python\python38-32\lib\site-packages\flask\app.py", line 1935, in dispatch_request
    return self.view_functions[rule.endpoint](**req.view_args)
  File "C:\Users\vogel\OneDrive\Desktop\CoronaLMS\app\routes.py", line 63, in login
    return render_template('login.html', title='Login', form=form)
  File "c:\users\vogel\appdata\local\programs\python\python38-32\lib\site-packages\flask\templating.py", line 137, in render_template
    return _render(
  File "c:\users\vogel\appdata\local\programs\python\python38-32\lib\site-packages\flask\templating.py", line 120, in _render
    rv = template.render(context)
  File "c:\users\vogel\appdata\local\programs\python\python38-32\lib\site-packages\jinja2\environment.py", line 1090, in render
    self.environment.handle_exception()
  File "c:\users\vogel\appdata\local\programs\python\python38-32\lib\site-packages\jinja2\environment.py", line 832, in handle_exception
    reraise(*rewrite_traceback_stack(source=source))
  File "c:\users\vogel\appdata\local\programs\python\python38-32\lib\site-packages\jinja2\_compat.py", line 28, in reraise
    raise value.with_traceback(tb)
  File "C:\Users\vogel\OneDrive\Desktop\CoronaLMS\app\templates\login.html", line 1, in top-level template code
    {% extends "base.html" %}
  File "c:\users\vogel\appdata\local\programs\python\python38-32\lib\site-packages\jinja2\environment.py", line 832, in handle_exception
    reraise(*rewrite_traceback_stack(source=source))
  File "c:\users\vogel\appdata\local\programs\python\python38-32\lib\site-packages\jinja2\_compat.py", line 28, in reraise
    raise value.with_traceback(tb)
  File "C:\Users\vogel\OneDrive\Desktop\CoronaLMS\app\templates\base.html", line 12, in template
    <link href="{{ url_for('static', filename='css/pricing.css) }}" rel="stylesheet">
jinja2.exceptions.TemplateSyntaxError: unexpected char "'" at 385
2020-04-14 21:07:17,502 ERROR: Exception on /login [GET] [in c:\users\vogel\appdata\local\programs\python\python38-32\lib\site-packages\flask\app.py:1890]
Traceback (most recent call last):
  File "c:\users\vogel\appdata\local\programs\python\python38-32\lib\site-packages\flask\app.py", line 2446, in wsgi_app
    response = self.full_dispatch_request()
  File "c:\users\vogel\appdata\local\programs\python\python38-32\lib\site-packages\flask\app.py", line 1951, in full_dispatch_request
    rv = self.handle_user_exception(e)
  File "c:\users\vogel\appdata\local\programs\python\python38-32\lib\site-packages\flask\app.py", line 1820, in handle_user_exception
    reraise(exc_type, exc_value, tb)
  File "c:\users\vogel\appdata\local\programs\python\python38-32\lib\site-packages\flask\_compat.py", line 39, in reraise
    raise value
  File "c:\users\vogel\appdata\local\programs\python\python38-32\lib\site-packages\flask\app.py", line 1949, in full_dispatch_request
    rv = self.dispatch_request()
  File "c:\users\vogel\appdata\local\programs\python\python38-32\lib\site-packages\flask\app.py", line 1935, in dispatch_request
    return self.view_functions[rule.endpoint](**req.view_args)
  File "C:\Users\vogel\OneDrive\Desktop\CoronaLMS\app\routes.py", line 63, in login
    return render_template('login.html', title='Login', form=form)
  File "c:\users\vogel\appdata\local\programs\python\python38-32\lib\site-packages\flask\templating.py", line 137, in render_template
    return _render(
  File "c:\users\vogel\appdata\local\programs\python\python38-32\lib\site-packages\flask\templating.py", line 120, in _render
    rv = template.render(context)
  File "c:\users\vogel\appdata\local\programs\python\python38-32\lib\site-packages\jinja2\environment.py", line 1090, in render
    self.environment.handle_exception()
  File "c:\users\vogel\appdata\local\programs\python\python38-32\lib\site-packages\jinja2\environment.py", line 832, in handle_exception
    reraise(*rewrite_traceback_stack(source=source))
  File "c:\users\vogel\appdata\local\programs\python\python38-32\lib\site-packages\jinja2\_compat.py", line 28, in reraise
    raise value.with_traceback(tb)
  File "C:\Users\vogel\OneDrive\Desktop\CoronaLMS\app\templates\login.html", line 1, in top-level template code
    {% extends "base.html" %}
  File "c:\users\vogel\appdata\local\programs\python\python38-32\lib\site-packages\jinja2\environment.py", line 832, in handle_exception
    reraise(*rewrite_traceback_stack(source=source))
  File "c:\users\vogel\appdata\local\programs\python\python38-32\lib\site-packages\jinja2\_compat.py", line 28, in reraise
    raise value.with_traceback(tb)
  File "C:\Users\vogel\OneDrive\Desktop\CoronaLMS\app\templates\base.html", line 12, in template
    <link href="{{ url_for('static', filename='css/pricing.css) }}" rel="stylesheet">
jinja2.exceptions.TemplateSyntaxError: unexpected char "'" at 385
2020-04-14 21:07:52,202 INFO: Corona LMS startup [in C:\Users\vogel\OneDrive\Desktop\CoronaLMS\app\__init__.py:38]
2020-04-14 21:08:12,515 ERROR: Exception on /login [GET] [in c:\users\vogel\appdata\local\programs\python\python38-32\lib\site-packages\flask\app.py:1890]
Traceback (most recent call last):
  File "c:\users\vogel\appdata\local\programs\python\python38-32\lib\site-packages\flask\app.py", line 2446, in wsgi_app
    response = self.full_dispatch_request()
  File "c:\users\vogel\appdata\local\programs\python\python38-32\lib\site-packages\flask\app.py", line 1951, in full_dispatch_request
    rv = self.handle_user_exception(e)
  File "c:\users\vogel\appdata\local\programs\python\python38-32\lib\site-packages\flask\app.py", line 1820, in handle_user_exception
    reraise(exc_type, exc_value, tb)
  File "c:\users\vogel\appdata\local\programs\python\python38-32\lib\site-packages\flask\_compat.py", line 39, in reraise
    raise value
  File "c:\users\vogel\appdata\local\programs\python\python38-32\lib\site-packages\flask\app.py", line 1949, in full_dispatch_request
    rv = self.dispatch_request()
  File "c:\users\vogel\appdata\local\programs\python\python38-32\lib\site-packages\flask\app.py", line 1935, in dispatch_request
    return self.view_functions[rule.endpoint](**req.view_args)
  File "C:\Users\vogel\OneDrive\Desktop\CoronaLMS\app\routes.py", line 63, in login
    return render_template('login.html', title='Login', form=form)
  File "c:\users\vogel\appdata\local\programs\python\python38-32\lib\site-packages\flask\templating.py", line 137, in render_template
    return _render(
  File "c:\users\vogel\appdata\local\programs\python\python38-32\lib\site-packages\flask\templating.py", line 120, in _render
    rv = template.render(context)
  File "c:\users\vogel\appdata\local\programs\python\python38-32\lib\site-packages\jinja2\environment.py", line 1090, in render
    self.environment.handle_exception()
  File "c:\users\vogel\appdata\local\programs\python\python38-32\lib\site-packages\jinja2\environment.py", line 832, in handle_exception
    reraise(*rewrite_traceback_stack(source=source))
  File "c:\users\vogel\appdata\local\programs\python\python38-32\lib\site-packages\jinja2\_compat.py", line 28, in reraise
    raise value.with_traceback(tb)
  File "C:\Users\vogel\OneDrive\Desktop\CoronaLMS\app\templates\login.html", line 1, in top-level template code
    {% extends "base.html" %}
  File "c:\users\vogel\appdata\local\programs\python\python38-32\lib\site-packages\jinja2\environment.py", line 832, in handle_exception
    reraise(*rewrite_traceback_stack(source=source))
  File "c:\users\vogel\appdata\local\programs\python\python38-32\lib\site-packages\jinja2\_compat.py", line 28, in reraise
    raise value.with_traceback(tb)
  File "C:\Users\vogel\OneDrive\Desktop\CoronaLMS\app\templates\base.html", line 12, in template
    <link href="{{ url_for('static', filename='css/pricing.css) }}" rel="stylesheet">
jinja2.exceptions.TemplateSyntaxError: unexpected char "'" at 385
2020-04-14 21:09:13,121 INFO: Corona LMS startup [in C:\Users\vogel\OneDrive\Desktop\CoronaLMS\app\__init__.py:38]
2020-04-14 21:15:30,847 INFO: Corona LMS startup [in C:\Users\vogel\OneDrive\Desktop\CoronaLMS\app\__init__.py:38]
2020-04-14 21:16:47,783 INFO: Corona LMS startup [in C:\Users\vogel\OneDrive\Desktop\CoronaLMS\app\__init__.py:38]
2020-04-15 06:54:24,912 INFO: Corona LMS startup [in C:\Users\vogel\OneDrive\Desktop\CoronaLMS\app\__init__.py:38]
2020-04-15 06:58:38,904 INFO: Corona LMS startup [in C:\Users\vogel\OneDrive\Desktop\CoronaLMS\app\__init__.py:38]
2020-04-15 07:00:56,638 INFO: Corona LMS startup [in C:\Users\vogel\OneDrive\Desktop\CoronaLMS\app\__init__.py:38]
2020-04-15 07:14:23,496 INFO: Corona LMS startup [in C:\Users\vogel\OneDrive\Desktop\CoronaLMS\app\__init__.py:38]
2020-04-15 07:19:56,585 INFO: Corona LMS startup [in C:\Users\vogel\OneDrive\Desktop\CoronaLMS\app\__init__.py:38]
2020-04-15 07:23:18,041 INFO: Corona LMS startup [in C:\Users\vogel\OneDrive\Desktop\CoronaLMS\app\__init__.py:38]
2020-04-15 07:27:11,878 INFO: Corona LMS startup [in C:\Users\vogel\OneDrive\Desktop\CoronaLMS\app\__init__.py:38]
